Workbook

Sheet Schedule
C1: Installers | G1: Assemblers
C2: Hao, Yaopeng, Mark, Wassim, Mitch, Christine, Josh | G2: 3 persons per shift
B3: time | C3: 45546 | D3: 45294 | E3: 45356 | G3: 45294 | H3: 45356 | I3: 45419
A4: Wed | B4: 45294 | C4: - | D4: - | E4: -
A5: Thu | B5: 45295 | C5: Hao-Yaopeng | D5: Wassim-Mitch | E5: Christine-Josh
A6: Fri | B6: 45296 | C6: board repairs | D6: Christine-Mark | E6: Hao-Yaopeng
A7: Sat | B7: 45297 | C7: Wassim-Mitch | D7: Christine-Mark | E7: Hao-Yaopeng
A8: Sun | B8: 45298
A9: Mon | B9: 45299 | C9: analysis meeting | D9: Mark-Hao | E9: Yaopeng-Wassim | G9: Yaopeng-Mitch-Casey | H9: Mike-Mark | I9: Julie-MArk-Josh
A10: Tue | B10: 45300 | C10: Christine-Mark | D10: Hao-Yaopeng | E10: Wassim-Mitch | G10: Mitch-Mark | H10: Yaopeng
A11: Wed | B11: 45301 | C11: Mark-Hao | D11: Yaopeng-Wassim | E11: Mitch-Christine | G11: Mitch-Mark-Christine | H11: Yaopeng-Wassim
A12: Thu | B12: 45302 | C12: analysis meeting | D12: Wassim-Mitch | E12: Christine-Mark | H12: Yaopeng-Mitch | I12: Mark-Wassim
A13: Fri | B13: 45303 | C13: Yaopeng-Wassim | D13: Mitch-Christine | E13: Mark-Hao | G13: Mike-Mark-Casey | H13: Yaopeng-Wassim-Christine
A14: Sat | B14: 45304 | C14: Wassim-Mitch | D14: Christine-Mark | E14: Hao-Yaopeng | H14: Mark
A15: Sun | B15: 45305
A16: Mon | B16: 45306 | C16: analysis meeting | D16: Mark-Hao | E16: Yaopeng-Wassim | H16: Mark-Christine
A17: Tue | B17: 45307 | C17: Christine-Mark | D17: Hao-Yaopeng | E17: Wassim-Mitch | G17: Mark
A18: Wed | B18: 45308 | C18: Mark-Hao | D18: Yaopeng-Wassim | E18: Mitch-Christine | G18: Mark
A19: Thu | B19: 45309 | C19: analysis meeting | D19: Wassim-Mitch | E19: Christine-Mark | G19: Mark
A20: Fri | B20: 45310 | C20: Yaopeng-Wassim | D20: Mitch-Christine | E20: Mark-Hao | G20: Mark
A21: Sat | B21: 45311 | C21: Wassim-Mitch | D21: Christine-Mark | E21: Hao-Yaopeng | H21: Mark
A22: Sun | B22: 45312
A23: Mon | B23: 45313 | C23: Beam is back

Sheet Special runs
A1: cosmics, LED, other stuff | H1: HV
A2: day | B2: run | C2: purpose
A3: sept 15 | B3: 1104 | C3: cosmics | D3: 10h | H3: cosmics | J3: https://logbooks.jlab.org/entry/4179529
A4: sept 20 | B4: 1298 | C4: cosmics | D4: 3h | J4: https://logbooks.jlab.org/entry/4183880
A5: sept 23 | B5: 1371 | C5: LED | D5: 40 min
A6: sept 23 | B6: 1370 | C6: LED | D6: 33 min
A7: sept 26 | B7: 1443 | C7: cosmics | D7: 6h | J7: https://logbooks.jlab.org/entry/4187682
A8: Sept 28 | B8: 1479 | C8: cosmics | D8: 8h | F8: TS2: 12411 | H8: HV-25V | J8: https://logbooks.jlab.org/entry/4188808
A9: sept 28 | B9: 1492 | C9: cosmics | D9: 3h | F9: TS2: 5873 | H9: HV-25V | J9: https://logbooks.jlab.org/entry/4188943
A10: 45201 | B10: 1563 | C10: cosmics | D10: 2h | F10: TS2:4031 | J10: https://logbooks.jlab.org/entry/4191130
A11: 45201 | B11: 1565 | C11: LED | D11: 33 min | F11: T2=24866153
A12: 45201 | B12: 1564 | C12: LED | D12: 33 min | F12: T2=23271036
B13: 1569 | C13: alignement check from 9 to 3 m | D13: from 9 to 3 m
B14: 1570 | C14: alignments check from 9 to 3m
A15: 45205 | B15: 1660 | C15: LED | D15: 23 min | F15: production HV
A16: 45210 | B16: 1771 | C16: LED | D16: 138 min
B17: 1772 | C17: LED | D17: 3 min | F17: https://logbooks.jlab.org/entry/4197192
B18: 1773 | C18: LED | D18: 26 min
B19: 1774 | C19: cosmics | D19: 2.5 h
A20: 45211 | B20: 1795 | C20: cosmics | D20: 4h
A21: 45216 | B21: Moller_1839 | D21: Start 12:15
B22: Moller_1840
B23: Moller_1841
B24: Moller_1842
B25: Moller_1843
B26: Moller_1844
B27: Moller_1845
B28: Moller_1846 | D28: End 15:26 | E28: Total time 3:11
B30: run | C30: purpose | D30: Ibeam (uA) | E30: HMS mom | F30: HMS angle | G30: SHMS angle | H30: calo angle | I30: calo distance | J30: target
A31: 45219 | B31: 1983 | C31: J/Psi background est | D31: 30 | E31: =5.878 -> 5.878 | F31: 16.48 | G31: 35.03 | H31: 18.76 | I31: 3 | J31: LH2
B32: 1984 | C32: J/Psi background est | D32: 30 | E32: =5.878 -> 5.878 | F32: 16.48 | G32: 35.03 | H32: 18.76 | I32: 3 | J32: LH2
B34: 1985 | C34: LED | D34: 2min | E34: 37000 events | F34: DAC=55 only col 16
B35: 1986 | C35: LED | D35: 2min | F35: DAC=55 only col 16
A37: 0ct-23rd | B37: 2133 | C37: Beam Studies | D37: 35mins | E37: T6 = 1925415 | F37: ps6=0 | G37: Ibeam ~ 22.68 | H37: 34.09mC
B38: 2134 | C38: DAQ Debug w/ Alexander | D38: 0.45208333
B39: ↓
B40: 2154 | D40: 0.53819444
B41: 2155 | C41: BCM Calib | D41: 9.71min | F41: ps6=0
B42: 2157 | C42: BCM Calib | D42: 132.22 mins | F42: ps6=0
A44: 45240 | B44: 2828 | C44: LED | D44: large WF window, col 12-14, dac=55
...

Sheet 5p_commissionning
E1: HMS mom | F1: HMS angle | G1: SHMS angle | H1: calo angle | I1: calo distance | L1: Collimator
A2: day | B2: run | C2: purpose | D2: Ibeam (uA) | J2: target | K2: Beam pass | M2: Presscale | N2: event # | O2: duration (min) | P2: Charge Accumulated | Q2: comments
A3: 45183 | B3: 1139 | C3: BPM calibration | D3: pulsed | I3: 9.5 | J3: none | K3: 5 | Q3: beam position ( -0.5 | 2.0 | -1.5 | 2.0)
B4: 1140 | C4: BPM calibration | D4: pulsed | I4: 9.5 | J4: none | K4: 5 | Q4: beam position ( -0.5 | -2.0 | -1.5 | -2.0)
B5: 1141 | C5: BPM calibration | D5: pulsed | I5: 9.5 | J5: none | K5: 5 | Q5: beam position (3.3 | 2.0 | 2.6 | 2.0)
B6: 1142 | C6: BPM calibration | D6: pulsed | I6: 9.5 | J6: none | K6: 5 | Q6: beam position (1.5 | 0.0 | 0.5 | 0.0)
A7: 45184 | B7: 1144 | C7: HMS checkout - Q2 defocused | D7: 10 | E7: -4.367 | F7: 36.2 | G7: =H7+16.3 -> 36.3 | H7: 20 | I7: 9.5 | J7: LD2 | K7: 5 | Q7: ps3=2
B8: 1145 | C8: HMS checkout - Q2 defocused | D8: 10 | E8: -4.367 | F8: 36.2 | G8: =H8+16.3 -> 36.3 | H8: 20 | I8: 9.5 | J8: LD2 | K8: 5 | Q8: ps3=2
B9: 1146 | C9: HMS check out - nominal Q2 | D9: 10 | E9: -4.367 | F9: 36.2 | G9: =H9+16.3 -> 36.3 | H9: 20 | I9: 9.5 | J9: LD2 | K9: 5 | Q9: ps3=2
B10: 1147 | C10: HMS check out - nominal Q2 | D10: 10 | E10: -4.367 | F10: 36.2 | G10: =H10+16.3 -> 36.3 | H10: 20 | I10: 9.5 | J10: LD2 | K10: 5 | Q10: ps3=2
B11: 1148 | C11: HMS checkout- FADC mode 10 | D11: 10 | E11: -4.367 | F11: 36.2 | G11: =H11+16.3 -> 36.3 | H11: 20 | I11: 9.5 | J11: LD2 | K11: 5
B12: 1149 | C12: HMS 3/4 | D12: 10 | E12: -4.367 | F12: 36.2 | G12: =H12+16.3 -> 36.3 | H12: 20 | I12: 9.5 | J12: LD2 | K12: 5
B13: 1150 | C13: HMS check out- 3/4 | D13: 10 | E13: -4.367 | F13: 36.2 | G13: =H13+16.3 -> 36.3 | H13: 20 | I13: 9.5 | J13: LD2 | K13: 5 | Q13: https://logbooks.jlab.org/entry/4180369
B14: 1151 | C14: HMs ELCLEAN | D14: 10 | E14: -4.367 | F14: 36.2 | G14: =H14+16.3 -> 36.3 | H14: 20 | I14: 9.5 | J14: LD2 | K14: 5
B15: 1153-1165 | C15: HMS optics (-3.6 GeV) | D15: 30 | E15: -4.367 | F15: 36.2 | G15: =H15+16.3 -> 36.3 | H15: 20 | I15: 9.5 | J15: C 0.5% | K15: 5
B16: 1166 | C16: Coincidence seeking | D16: 5 | E16: -6.8 | F16: 12.49 | G16: =H16+16.3 -> 37.1 | H16: 20.8 | I16: 9.5 | J16: C 0.5% | K16: 5 | Q16: x50-2
B17: 1167-1173 | C17: Coincidence seeking | D17: 5 | E17: -6.8 | F17: 12.49 | G17: =H17+16.3 -> 37.1 | H17: 20.8 | I17: 9.5 | J17: LD2 | K17: 5 | Q17: x50-2
A18: 45186 | B18: 1174-1187 | C18: Coincidence seeking | D18: 5 | E18: =4.036 -> 4.036 | F18: 30.14 | G18: =H18+16.3 -> 33.19 | H18: 16.89 | I18: 9.5 | J18: LD2 | K18: 5 | Q18: elastic (large angle), proton in HMS
B19: 1188-1193 | C19: HMS optic at -6.117 | D19: 30 | E19: -6.117 | F19: 12.373 | G19: =H19+16.3 -> 37 | H19: 20.7 | I19: 9.5 | J19: C 0.5% | K19: 5 | Q19: https://logbooks.jlab.org/entry/4181512
B20: 1194-1214 | C20: NPS trigger test, initial setup | D20: 5 | E20: =4.036 -> 4.036 | F20: 30.14 | G20: =H20+16.3 -> 30.9 | H20: =30.9-16.3 -> 14.6 | I20: 9.5 | J20: LH2 | K20: 5 | Q20: elastic (small angle), proton in HMS
B21: 1215 | C21: NPS trigger test, | D21: 5 | E21: =4.036 -> 4.036 | F21: 30.14 | G21: =H21+16.3 -> 30.9 | H21: =30.9-16.3 -> 14.6 | I21: 9.5 | J21: LH2 | K21: 5 | Q21: elastic (small angle), proton in HMS | R21: th=500, seed th=300, output th 1000
B22: 1216 | C22: NPS trigger test, | D22: 5 | E22: =4.036 -> 4.036 | F22: 30.14 | G22: =H22+16.3 -> 30.9 | H22: =30.9-16.3 -> 14.6 | I22: 9.5 | J22: LH2 | K22: 5 | Q22: elastic (small angle), proton in HMS | R22: th=500, seed th=300, output th =1000
B23: 1217 | C23: NPS trigger test, | D23: 5 | E23: =4.036 -> 4.036 | F23: 30.14 | G23: =H23+16.3 -> 30.9 | H23: =30.9-16.3 -> 14.6 | I23: 9.5 | J23: LH2 | K23: 5 | Q23: elastic (small angle), proton in HMS | R23: th=500, seed th=300, output th =500
B24: 1218 | C24: NPS trigger test | D24: 5 | E24: =4.036 -> 4.036 | F24: 30.14 | G24: =H24+16.3 -> 30.9 | H24: =30.9-16.3 -> 14.6 | I24: 9.5 | J24: LH2 | K24: 5 | Q24: elastic (small angle), proton in HMS | R24: th=1000, seed th=300, output th =500
B25: 1219 | C25: NPS trigger test | D25: 5 | E25: =4.036 -> 4.036 | F25: 30.14 | G25: =H25+16.3 -> 30.9 | H25: =30.9-16.3 -> 14.6 | I25: 9.5 | J25: LH2 | K25: 5 | Q25: elastic (small angle), proton in HMS | R25: th=2000, seed th=300, output th =500
B26: 1220 | C26: NPS trigger test | D26: 5 | E26: =4.036 -> 4.036 | F26: 30.14 | G26: =H26+16.3 -> 30.9 | H26: =30.9-16.3 -> 14.6 | I26: 9.5 | J26: LH2 | K26: 5 | Q26: elastic (small angle), proton in HMS | R26: th=4000, seed th=300, output th =500
B27: 1221 | C27: NPS trigger test | D27: 5 | E27: =4.036 -> 4.036 | F27: 30.14 | G27: =H27+16.3 -> 30.9 | H27: =30.9-16.3 -> 14.6 | I27: 9.5 | J27: LH2 | K27: 5 | Q27: elastic (small angle), proton in HMS | R27: th=2000, seed th=600, output th =500
B28: 1222-1237 | C28: NPS trigger test | D28: 5 | E28: =4.036 -> 4.036 | F28: 30.14 | G28: 30.9 | H28: =30.9-16.3 -> 14.6 | I28: 9.5 | J28: LH2 | K28: 5 | Q28: elastic (small angle), proton in HMS
B29: 1238 | C29: NPS trigger test | D29: 5 | E29: =4.036 -> 4.036 | F29: 30.14 | G29: 32.05 | H29: =G29-16.3 -> 15.75 | I29: 9.5 | J29: LH2 | K29: 5 | N29: 216k | Q29: elastic middle angle, proton in HMS
B30: 1239 | C30: NPS trigger test | D30: 5 | E30: =4.036 -> 4.036 | F30: 30.14 | G30: 33.19 | H30: =G30-16.3 -> 16.89 | I30: 9.5 | J30: LH2 | K30: 5 | N30: 125k | Q30: elastic (large angle), proton in HMS
B31: 1240 | D31: 30 | E31: -6.117 | F31: 12.373 | G31: =H31+16.3 -> 37 | H31: 20.7 | I31: 9.5 | J31: LH2 | K31: 5 | Q31: electron in HMS*
F33: CHECK LOG BOOK FOR PHOTOS | R33: Below are from Start of the run info, need to verify the angle from camera !!!
A34: 45187 | B34: 1241 | C34: HMS optics | D34: 10 | E34: -6.117 | F34: 12.38 | G34: 37.3 | H34: =37.3-16.3 -> 21 | I34: 9.5 | J34: Optics 1 +/- 8cm | K34: 5 | Q34: ps4 = 0
B35: 1242 | C35: HMS optics | D35: 30 | E35: -6.117 | F35: 12.38 | G35: 37.3 | H35: =37.3-16.3 -> 21 | I35: 9.5 | J35: Optics 1 +/- 8cm | K35: 5 | Q35: ps4 = 0
B36: 1243 | C36: HMS optics | D36: 30 | E36: -6.117 | F36: 12.38 | G36: 37.3 | H36: =37.3-16.3 -> 21 | I36: 9.5 | J36: Optics 1 +/- 8cm | K36: 5 | Q36: ps4 = 0 | R36: comment_text=EL-REAL Trigger ; TET_IGNORE_MAKS all 0 ; TET = 500 ; Sparsification set to 1
B37: 1244 | C37: HMS optics | D37: 30 | E37: -6.117 | F37: 12.38 | G37: 37.3 | H37: =37.3-16.3 -> 21 | I37: 9.5 | J37: Optics 1 +/- 8cm | K37: 5 | Q37: ps4 = 0 | R37: comment_text=EL-REAL Trigger ; TET_IGNORE_MAKS all 0 ; TET = 500 ; Sparsification set to 1
A38: 45188 | B38: 1245 | C38: HMS optics | D38: 30 | E38: -6.117 | F38: 12.38 | G38: 37.3 | H38: =37.3-16.3 -> 21 | I38: 9.5 | J38: Carbon 0.5% | K38: 5 | Q38: ps4 = 0 | R38: comment_text=EL-REAL Trigger ; TET_IGNORE_MAKS all 0 ; TET = 500 ; Sparsification set to 1; Sweeper magnet ON; C 0.5%
B39: 1246 | C39: HMS optics | D39: 30 | E39: -6.117 | F39: 12.38 | G39: 37.3 | H39: =37.3-16.3 -> 21 | I39: 9.5 | J39: Optics 1 +/- 8cm | K39: 5 | Q39: ps4 = 0 | R39: comment_text=EL-REAL Trigger ; TET_IGNORE_MAKS all 0 ; TET = 500 ; Sparsification set to 1; Sweeper magnet ON; optics foil +-8cm
B40: 1247 | C40: CODA CRASHED, NO END OF RUN INFO, SKIPPED
B41: 1248 | C41: HMS optics | D41: 30 | E41: -6.117 | F41: 12.38 | G41: 37.3 | H41: =37.3-16.3 -> 21 | I41: 9.5 | J41: Optics 2 +/- 3cm | K41: 5 | Q41: ps4 = 0 | R41: comment_text=EL-REAL Trigger ; TET_IGNORE_MAKS all 0 ; TET = 500 ; Sparsification set to 1; Sweeper magnet OFF; optics foil +-3cm
...

Sheet 4p_commissionning
E1: HMS mom | F1: HMS angle | G1: SHMS angle | H1: calo angle | I1: calo distance | L1: Collimator
A2: day | B2: run | C2: purpose | D2: Ibeam (uA) | J2: target | K2: Beam pass | M2: Presscale | N2: event # | O2: duration (min) | P2: Charge Accumulated | Q2: comments
A3: 45243 | B3: 2886 | C3: Beam centering | D3: 10 | E3: 4.12 | F3: 27.615 | G3: 38 | H3: =G3-16.3 -> 21.7 | I3: 8 | J3: Carbon Hole | K3: 4 | L3: L | M3: ps3=0 | Q3: Still no beam from shift summary
A4: 45244 | B4: 2898 | C4: Beam centering | D4: 10 | E4: 4.12 | F4: 27.615 | G4: 38 | H4: =G4-16.3 -> 21.7 | I4: 8 | J4: Carbon Hole | K4: 4 | L4: L | M4: ps4=0 | N4: 62834 | O4: 25.66 | P4: 11 | Q4: Carbon hole not really visible too faint
B5: 2899 | C5: Beam centering | D5: 10 | E5: 4.12 | F5: 27.615 | G5: 38 | H5: =G5-16.3 -> 21.7 | I5: 8 | J5: Carbon Hole | K5: 4 | L5: L | M5: ps3=0 | N5: 63388 | O5: 22.22 | P5: 11.79 | Q5: Carbon hole is still faint, but is visible and centered
B6: 2900 | C6: Elastic Calibration | D6: 40 | E6: 4.12 | F6: 27.615 | G6: 38 | H6: =G6-16.3 -> 21.7 | I6: 8 | J6: LH2 | K6: 4 | L6: L | M6: ps5=0 | N6: 158628 | O6: 65.26 | P6: 118.11 | Q6: FADC coefficeint error
B7: 2901 | C7: Elastic Calibration | D7: 40 | E7: 4.12 | F7: 27.615 | G7: 38 | H7: =G7-16.3 -> 21.7 | I7: 8 | J7: LH2 | K7: 4 | L7: L | M7: ps5=0 | N7: 147642 | O7: 60.05 | P7: 116.68 | Q7: FADC coefficeint error
B8: 2902 | C8: Elastic Calibration | D8: 40 | E8: 4.12 | F8: 27.615 | G8: 38 | H8: =G8-16.3 -> 21.7 | I8: 8 | J8: LH2 | K8: 4 | L8: L | M8: ps5=0 | N8: 4098 | O8: 13.49 | P8: 26.26 | Q8: FADC coefficeint error
B9: 2903 | C9: Elastic Calibration | D9: 40 | E9: 4.12 | F9: 27.615 | G9: 38 | H9: =G9-16.3 -> 21.7 | I9: 8 | J9: LH2 | K9: 4 | L9: L | M9: ps3=0 | N9: 525993 | O9: 54.21 | P9: 114.12 | Q9: run with ps3=0 to work around the fadc issue
B10: 2904 | C10: Elastic Calibration | D10: 40 | E10: 4.12 | F10: 27.615 | G10: 38 | H10: =G10-16.3 -> 21.7 | I10: 8 | J10: LH2 | K10: 4 | L10: L | M10: ps3=0 | N10: 146004 | O10: 19.83 | P10: 41.03 | Q10: run with ps3=0 to work around the fadc issue
B11: 2905 | C11: Elastic Calibration | D11: 40 | E11: 4.12 | F11: 27.615 | G11: 38 | H11: =G11-16.3 -> 21.7 | I11: 8 | J11: LH2 | K11: 4 | L11: L | M11: ps3=0 | N11: 458583 | O11: 68.22 | P11: 127.95 | Q11: New FADC values loaded but still in ps3 to verify
B12: 2906 | C12: Elastic Calibration | D12: 40 | E12: 4.12 | F12: 27.615 | G12: 38 | H12: =G12-16.3 -> 21.7 | I12: 8 | J12: LH2 | K12: 4 | L12: L | M12: ps5=0 | N12: 53017 | O12: 58.42 | P12: 112.38 | Q12: New FADC values loaded run in ps5
B13: 2907 | C13: Elastic Calibration | D13: 40 | E13: 4.12 | F13: 27.615 | G13: 36.138 | H13: =G13-16.3 -> 19.838 | I13: 8 | J13: LH2 | K13: 4 | L13: L | M13: ps5=0 | N13: 58318 | O13: 59.32 | P13: 126.99
B14: 2908 | C14: Elastic Calibration | D14: 40 | E14: 4.12 | F14: 27.615 | G14: 36.138 | H14: =G14-16.3 -> 19.838 | I14: 8 | J14: LH2 | K14: 4 | L14: L | M14: ps5=0 | N14: 6395 | O14: 6.07 | P14: 14.1 | Q14: run ended for magnet rampdown to replace JT
B15: 2909 | C15: Elastic Calibration | D15: 40 | E15: 4.12 | F15: 27.615 | G15: 36.138 | H15: =G15-16.3 -> 19.838 | I15: 8 | J15: LH2 | K15: 4 | L15: L | M15: ps5=0 | N15: 65066 | O15: 75.91 | P15: 133.88
B16: 2910 | C16: Elastic Calibration | D16: 40 | E16: 4.12 | F16: 27.615 | G16: 36.138 | H16: =G16-16.3 -> 19.838 | I16: 8 | J16: LH2 | K16: 4 | L16: L | M16: ps5=0 | N16: 66290 | O16: 71.94 | P16: 142.36
B17: 2911 | C17: Elastic Calibration | D17: 40 | E17: 4.12 | F17: 27.615 | G17: 37.997 | H17: =G17-16.3 -> 21.697 | I17: 8 | J17: LH2 | K17: 4 | L17: L | M17: ps5=0 | N17: 67109 | O17: 71.93 | P17: 142.41
B18: 2912 | C18: Elastic Calibration | D18: 40 | E18: 4.12 | F18: 27.615 | G18: 37.997 | H18: =G18-16.3 -> 21.697 | I18: 8 | J18: LH2 | K18: 4 | L18: L | M18: ps5=0 | N18: 62406 | O18: 64.09 | P18: 136.09
B19: 2913 | C19: Elastic Calibration | D19: 40 | E19: 4.12 | F19: 27.615 | G19: 37.997 | H19: =G19-16.3 -> 21.697 | I19: 8 | J19: LH2 | K19: 4 | L19: L | M19: ps5=0 | N19: 63625 | O19: 64.97 | P19: 138.49
B20: 2914 | C20: Elastic Calibration | D20: 40 | E20: 4.12 | F20: 27.615 | G20: 36.141 | H20: =G20-16.3 -> 19.841 | I20: 8 | J20: LH2 | K20: 4 | L20: L | M20: ps5=0 | N20: 61727 | O20: 62.06 | P20: 137.73
B21: 2915 | C21: Elastic Calibration | D21: 40 | E21: 4.12 | F21: 27.615 | G21: 36.141 | H21: =G21-16.3 -> 19.841 | I21: 8 | J21: LH2 | K21: 4 | L21: L | M21: ps5=0 | N21: 63018 | O21: 64.74 | P21: 138.2
A22: 45245 | B22: 2916 | C22: Elastic Calibration | D22: 40 | E22: 4.12 | F22: 27.615 | G22: 36.141 | H22: =G22-16.3 -> 19.841 | I22: 8 | J22: LH2 | K22: 4 | L22: L | M22: ps5=0 | N22: 63131 | O22: 65.89 | P22: 138.46
B23: 2917 | C23: Elastic Calibration | D23: 40 | E23: 4.12 | F23: 27.615 | G23: 38.002 | H23: =G23-16.3 -> 21.702 | I23: 8 | J23: LH2 | K23: 4 | L23: L | M23: ps5=0 | N23: 62087 | O23: 65.41 | P23: 132.71
B24: 2918 | C24: Elastic Calibration | D24: 40 | E24: 4.12 | F24: 27.615 | G24: 38.002 | H24: =G24-16.3 -> 21.702 | I24: 8 | J24: LH2 | K24: 4 | L24: L | M24: ps5=0 | N24: 62012 | O24: 66.08 | P24: 132.9
B25: 2919 | C25: Elastic Calibration | D25: 40 | E25: 4.12 | F25: 27.615 | G25: 38.002 | H25: =G25-16.3 -> 21.702 | I25: 8 | J25: LH2 | K25: 4 | L25: L | M25: ps5=0 | N25: 62266 | O25: 65.07 | P25: 136.42
B26: 2920 | C26: Elastic Calibration | D26: 40 | E26: 4.12 | F26: 27.615 | G26: 36.143 | H26: =G26-16.3 -> 19.843 | I26: 8 | J26: LH2 | K26: 4 | L26: L | M26: ps5=0 | N26: 61360 | O26: 67.31 | P26: 131.17
Q27: =SUM(P4:P26)/1000 -> 2.46123
A28: 45406 | B28: 6171 | C28: Elastic Calibration | D28: 20 | E28: 3.1615 | F28: 30.765 | G28: 36.265 | H28: =G28-13.3 -> 22.965 | I28: 9.5 | J28: LH2 | K28: 4 | L28: L | M28: ps5=0 | N28: 24300 | O28: 32.25 | P28: 33.8
B29: 6172 | C29: Elastic Calibration | D29: 20 | E29: 3.1615 | F29: 30.765 | G29: 36.265 | H29: =G29-13.3 -> 22.965 | I29: 9.5 | J29: LH2 | K29: 4 | L29: L | M29: ps5=0 | N29: 21366 | O29: 31.95 | P29: 27.18
B30: 6173 | C30: Elastic Calibration | D30: 20 | E30: 3.1615 | F30: 30.765 | G30: 35.06 | H30: =G30-13.3 -> 21.76 | I30: 9.5 | J30: LH2 | K30: 4 | L30: L | M30: ps5=0 | N30: 24274 | O30: 34.96 | P30: 29.18
B31: 6174 | C31: Elastic Calibration | D31: 20 | E31: 3.1615 | F31: 30.765 | G31: 35.06 | H31: =G31-13.3 -> 21.76 | I31: 9.5 | J31: LH2 | K31: 4 | L31: L | M31: ps5=0 | N31: 24307 | O31: 31.97 | P31: 30.98
B32: 6175 | C32: Elastic Calibration | D32: 20 | E32: 3.1615 | F32: 30.765 | G32: 33.855 | H32: =G32-13.3 -> 20.555 | I32: 9.5 | J32: LH2 | K32: 4 | L32: L | M32: ps5=0 | N32: 23163 | O32: 32.31 | P32: 33.43
B33: 6176 | C33: Elastic Calibration | D33: 20 | E33: 3.1615 | F33: 30.765 | G33: 33.855 | H33: =G33-13.3 -> 20.555 | I33: 9.5 | J33: LH2 | K33: 4 | L33: L | M33: ps5=0 | N33: 20737 | O33: 29.98 | P33: 28.9
B34: 6177 | C34: Elastic Calibration | D34: 20 | E34: 3.1615 | F34: 30.765 | G34: 36.262 | H34: =G34-13.3 -> 22.962 | I34: 9.5 | J34: LH2 | K34: 4 | L34: L | M34: ps5=0 | N34: 21522 | O34: 31.29 | P34: 27.62
B35: 6178 | C35: Elastic Calibration | D35: 20 | E35: 3.1615 | F35: 30.765 | G35: 35.058 | H35: =G35-13.3 -> 21.758 | I35: 9.5 | J35: LH2 | K35: 4 | L35: L | M35: ps5=0 | N35: 22004 | O35: 23.6 | P35: 30.18
B36: 6179 | C36: Elastic Calibration | D36: 30 | E36: 3.1615 | F36: 30.765 | G36: 33.85 | H36: =G36-13.3 -> 20.55 | I36: 9.5 | J36: LH2 | K36: 4 | L36: L | M36: ps5=0 | N36: 35501 | O36: 30.08 | P36: 59.92
B37: 6180 | C37: Elastic Calibration | D37: 38 | E37: 3.1615 | F37: 30.765 | G37: 33.85 | H37: =G37-13.3 -> 20.55 | I37: 9.5 | J37: LH2 | K37: 4 | L37: L | M37: ps5=0 | N37: 46708 | O37: 45.41 | P37: 72.59 | Q37: Updated NPS HV
B38: 6181 | C38: junk | D38: 38 | E38: 3.1615 | F38: 30.765 | G38: 35.053 | H38: =G38-13.3 -> 21.753 | I38: 9.5 | J38: LH2 | K38: 4 | L38: L | M38: ps5=0 | N38: 0 | O38: 0 | P38: 0 | Q38: Updated NPS HV
B39: 6182 | C39: Elastic Calibration | D39: 38 | E39: 3.1615 | F39: 30.765 | G39: 35.053 | H39: =G39-13.3 -> 21.753 | I39: 9.5 | J39: LH2 | K39: 4 | L39: L | M39: ps5=0 | N39: 55731 | O39: 44.07 | P39: 83.8 | Q39: Updated NPS HV
B40: 6183 | C40: Elastic Calibration | D40: 38 | E40: 3.1615 | F40: 30.765 | G40: 36.26 | H40: =G40-13.3 -> 22.96 | I40: 9.5 | J40: LH2 | K40: 4 | L40: L | M40: ps5=0 | N40: 45624 | O40: 42.34 | P40: 71.42 | Q40: Updated NPS HV

Sheet KinC_x50_2
F1: HMS mom | G1: HMS angle | H1: SHMS angle | I1: calo angle | L1: calo distance | N1: Required Charge Total (Coulomb)
A2: sweeper satus | B2: https://logbooks.jlab.org/entry/4191561 | F2: -6.667 GeV | G2: 12.493 deg | H2: 36.88 deg | I2: 20.58 deg | L2: 3 m | N2: ='Totals % Goal'!F16 -> 3
O3: accumulated charge (mC)
A4: day | B4: run# | C4: type | D4: SHMS angle | E4: Ibeam (uA) | F4: charge (mC) | G4: TS6 event # | H4: duration (min) | I4: target | J4: prescale | K4: coin status | O4: LH2 | P4: LD2 | Q4: Dummy
A5: 45202 | B5: 1572 | E5: 18 | F5: 8.99 | G5: 1564981 | H5: 21 | I5: LH2 | J5: ps5=0 | O5: =F5 -> 8.99 | P5: 0 | Q5: 0
B6: 1573 | C6: junk | I6: LH2 | J6: ps5=0 | O6: =if($I6="LH2",O5+$F6,O5+0) -> 8.99 | P6: =if($I6="LD2",P5+$F6,P5+0) -> 0 | Q6: =if($I6="dummy",Q5+$F6,Q5+0) -> 0
B7: 1574 | E7: 28 | F7: 49.79 | G7: 7597462 | H7: 30 | I7: LH2 | J7: ps5=0 | O7: =if($I7="LH2",O6+$F7,O6+0) -> 58.78 | P7: =if($I7="LD2",P6+$F7,P6+0) -> 0 | Q7: =if($I7="dummy",Q6+$F7,Q6+0) -> 0
B8: 1575 | E8: 19 | F8: 24.45 | G8: 4109623 | H8: 21 | I8: LH2 | J8: ps5=0 | O8: =if($I8="LH2",O7+$F8,O7+0) -> 83.23 | P8: =if($I8="LD2",P7+$F8,P7+0) -> 0 | Q8: =if($I8="dummy",Q7+$F8,Q7+0) -> 0
B9: 1576 | E9: 20 | F9: 31.59 | G9: 3464807 | H9: 28 | I9: LH2 | J9: ps5=0 | L9: pair th=500, cluster th=300 | O9: =if($I9="LH2",O8+$F9,O8+0) -> 114.82 | P9: =if($I9="LD2",P8+$F9,P8+0) -> 0 | Q9: =if($I9="dummy",Q8+$F9,Q8+0) -> 0
B10: 1577 | E10: 20 | F10: 30.82 | G10: 1883667 | H10: 29 | I10: LH2 | J10: ps5=0 | L10: pair th =100 | O10: =if($I10="LH2",O9+$F10,O9+0) -> 145.64 | P10: =if($I10="LD2",P9+$F10,P9+0) -> 0 | Q10: =if($I10="dummy",Q9+$F10,Q9+0) -> 0
B11: 1578 | E11: 19 | F11: 66.37 | G11: 4081085 | H11: 59 | I11: LH2 | J11: ps5=0 | O11: =if($I11="LH2",O10+$F11,O10+0) -> 212.01 | P11: =if($I11="LD2",P10+$F11,P10+0) -> 0 | Q11: =if($I11="dummy",Q10+$F11,Q10+0) -> 0
B12: 1579 | E12: 19 | F12: 29.46 | G12: 1570531 | H12: 29 | I12: dummy | J12: ps5=0 | O12: =if($I12="LH2",O11+$F12,O11+0) -> 212.01 | P12: =if($I12="LD2",P11+$F12,P11+0) -> 0 | Q12: =if($I12="dummy",Q11+$F12,Q11+0) -> 29.46
B13: 1580 | E13: 17 | F13: 18.1 | G13: 7294678 | H13: 17 | I13: LD2 | J13: ps5=0 | O13: =if($I13="LH2",O12+$F13,O12+0) -> 212.01 | P13: =if($I13="LD2",P12+$F13,P12+0) -> 18.1 | Q13: =if($I13="dummy",Q12+$F13,Q12+0) -> 29.46
B14: 1581 | C14: junk | I14: LD2 | J14: ps5=0 | O14: =if($I14="LH2",O13+$F14,O13+0) -> 212.01 | P14: =if($I14="LD2",P13+$F14,P13+0) -> 18.1 | Q14: =if($I14="dummy",Q13+$F14,Q13+0) -> 29.46
B15: 1582 | E15: 10 | F15: 10.05 | G15: 7342543 | H15: 19 | I15: LD2 | J15: ps5=0 | L15: lifetime 100% | O15: =if($I15="LH2",O14+$F15,O14+0) -> 212.01 | P15: =if($I15="LD2",P14+$F15,P14+0) -> 28.15 | Q15: =if($I15="dummy",Q14+$F15,Q14+0) -> 29.46
B16: 1583 | E16: 15 | G16: 4333615 | H16: 18 | I16: LD2 | J16: ps5=0 | L16: lifetime 75% | M16: end of run report stuck | O16: =if($I16="LH2",O15+$F16,O15+0) -> 212.01 | P16: =if($I16="LD2",P15+$F16,P15+0) -> 28.15 | Q16: =if($I16="dummy",Q15+$F16,Q15+0) -> 29.46
B17: 1584 | E17: 15 | G17: 13591086 | H17: 55 | I17: LD2 | J17: ps6=0 | M17: end of run report stuck | O17: =if($I17="LH2",O16+$F17,O16+0) -> 212.01 | P17: =if($I17="LD2",P16+$F17,P16+0) -> 28.15 | Q17: =if($I17="dummy",Q16+$F17,Q16+0) -> 29.46
B18: 1585 | C18: efficiency | E18: 20 | G18: 4370909 | H18: 34 | I18: LD2 | J18: ps3=5 | M18: end of run report stuck | O18: =if($I18="LH2",O17+$F18,O17+0) -> 212.01 | P18: =if($I18="LD2",P17+$F18,P17+0) -> 28.15 | Q18: =if($I18="dummy",Q17+$F18,Q17+0) -> 29.46
B19: 1586 | C19: junk | I19: LD2 | M19: end of run report stuck | O19: =if($I19="LH2",O18+$F19,O18+0) -> 212.01 | P19: =if($I19="LD2",P18+$F19,P18+0) -> 28.15 | Q19: =if($I19="dummy",Q18+$F19,Q18+0) -> 29.46
B20: 1587 | C20: junk | I20: LD2 | M20: end of run report stuck | O20: =if($I20="LH2",O19+$F20,O19+0) -> 212.01 | P20: =if($I20="LD2",P19+$F20,P19+0) -> 28.15 | Q20: =if($I20="dummy",Q19+$F20,Q19+0) -> 29.46
B21: 1588 | C21: efficiency | E21: 30 | G21: 1536606 | H21: 28 | I21: LH2 | J21: ps3=4 | M21: end of run report stuck | O21: =if($I21="LH2",O20+$F21,O20+0) -> 212.01 | P21: =if($I21="LD2",P20+$F21,P20+0) -> 28.15 | Q21: =if($I21="dummy",Q20+$F21,Q20+0) -> 29.46
B22: 1589 | E22: 30 | G22: 6931773 | H22: 55 | I22: LH2 | J22: ps6=0 | O22: =if($I22="LH2",O21+$F22,O21+0) -> 212.01 | P22: =if($I22="LD2",P21+$F22,P21+0) -> 28.15 | Q22: =if($I22="dummy",Q21+$F22,Q21+0) -> 29.46
B23: 1590 | E23: 23 | F23: 6.66 | G23: 5156019 | H23: 9 | I23: LH2 | J23: ps6=0 | O23: =if($I23="LH2",O22+$F23,O22+0) -> 218.67 | P23: =if($I23="LD2",P22+$F23,P22+0) -> 28.15 | Q23: =if($I23="dummy",Q22+$F23,Q22+0) -> 29.46
B24: 1591 | E24: 30 | H24: 65 | I24: LH2 | J24: ps6=0 | M24: no end of run report coda problems | O24: =if($I24="LH2",O23+$F24,O23+0) -> 218.67 | P24: =if($I24="LD2",P23+$F24,P23+0) -> 28.15 | Q24: =if($I24="dummy",Q23+$F24,Q23+0) -> 29.46
B25: 1592 | C25: junk | I25: LH2 | O25: =if($I25="LH2",O24+$F25,O24+0) -> 218.67 | P25: =if($I25="LD2",P24+$F25,P24+0) -> 28.15 | Q25: =if($I25="dummy",Q24+$F25,Q24+0) -> 29.46
B26: 1593 | C26: efficicency | E26: 19 | F26: 18.44 | G26: 1177009 | H26: 23 | I26: LH2 | J26: ps3=4 | O26: =if($I26="LH2",O25+$F26,O25+0) -> 237.11 | P26: =if($I26="LD2",P25+$F26,P25+0) -> 28.15 | Q26: =if($I26="dummy",Q25+$F26,Q25+0) -> 29.46
B27: 1594 | C27: efficicency | E27: 19 | F27: 19.78 | G27: 1261737 | H27: 19 | I27: LH2 | J27: ps3=4 | O27: =if($I27="LH2",O26+$F27,O26+0) -> 256.89 | P27: =if($I27="LD2",P26+$F27,P26+0) -> 28.15 | Q27: =if($I27="dummy",Q26+$F27,Q26+0) -> 29.46
B28: 1595 | E28: 26 | F28: 51.66 | G28: 4277011 | H28: 33 | I28: dummy | J28: ps6=0 | O28: =if($I28="LH2",O27+$F28,O27+0) -> 256.89 | P28: =if($I28="LD2",P27+$F28,P27+0) -> 28.15 | Q28: =if($I28="dummy",Q27+$F28,Q27+0) -> 81.12
A29: 45203 | B29: 1596 | E29: 14 | F29: 19.68 | G29: 6436948 | H29: 33 | I29: LD2 | J29: ps6=0 | O29: =if($I29="LH2",O28+$F29,O28+0) -> 256.89 | P29: =if($I29="LD2",P28+$F29,P28+0) -> 47.83 | Q29: =if($I29="dummy",Q28+$F29,Q28+0) -> 81.12
B30: 1597 | E30: 13 | F30: 36.23 | G30: 12165745 | H30: 58 | I30: LD2 | J30: ps6=0 | O30: =if($I30="LH2",O29+$F30,O29+0) -> 256.89 | P30: =if($I30="LD2",P29+$F30,P29+0) -> 84.06 | Q30: =if($I30="dummy",Q29+$F30,Q29+0) -> 81.12
B31: 1598 | E31: 14 | F31: 45.8 | G31: 15126845 | H31: 63 | I31: LD2 | J31: ps6=0 | O31: =if($I31="LH2",O30+$F31,O30+0) -> 256.89 | P31: =if($I31="LD2",P30+$F31,P30+0) -> 129.86 | Q31: =if($I31="dummy",Q30+$F31,Q30+0) -> 81.12
B32: 1599 | E32: 15 | G32: 3820866 | H32: 60 | I32: LD2 | J32: ps6=0 | M32: no end of run report coda problems | O32: =if($I32="LH2",O31+$F32,O31+0) -> 256.89 | P32: =if($I32="LD2",P31+$F32,P31+0) -> 129.86 | Q32: =if($I32="dummy",Q31+$F32,Q31+0) -> 81.12
B33: 1600 | E33: 15 | H33: 60 | I33: LD2 | J33: ps6=0 | M33: no end of run report | O33: =if($I33="LH2",O32+$F33,O32+0) -> 256.89 | P33: =if($I33="LD2",P32+$F33,P32+0) -> 129.86 | Q33: =if($I33="dummy",Q32+$F33,Q32+0) -> 81.12
B34: 1601-1609 | C34: junk | I34: LD2 | J34: ps6=0 | M34: coda issue | O34: =if($I34="LH2",O33+$F34,O33+0) -> 256.89 | P34: =if($I34="LD2",P33+$F34,P33+0) -> 129.86 | Q34: =if($I34="dummy",Q33+$F34,Q33+0) -> 81.12
B35: 1610 | C35: efficicency | E35: 14 | F35: 19.9 | G35: 6323301 | H35: 29 | I35: LD2 | J35: ps3=5 | O35: =if($I35="LH2",O34+$F35,O34+0) -> 256.89 | P35: =if($I35="LD2",P34+$F35,P34+0) -> 149.76 | Q35: =if($I35="dummy",Q34+$F35,Q34+0) -> 81.12
B36: 1611 | C36: junk | I36: LD2 | J36: ps6=0 | L36: testing pair threshol | O36: =if($I36="LH2",O35+$F36,O35+0) -> 256.89 | P36: =if($I36="LD2",P35+$F36,P35+0) -> 149.76 | Q36: =if($I36="dummy",Q35+$F36,Q35+0) -> 81.12
B37: 1612 | E37: 14 | F37: 1.19 | G37: 211210 | H37: 2 | I37: LD2 | J37: ps6=0 | O37: =if($I37="LH2",O36+$F37,O36+0) -> 256.89 | P37: =if($I37="LD2",P36+$F37,P36+0) -> 150.95 | Q37: =if($I37="dummy",Q36+$F37,Q36+0) -> 81.12
B38: 1613 | E38: 14 | F38: 40.79 | G38: 5524224 | H38: 68 | I38: LD2 | J38: ps6=0 | O38: =if($I38="LH2",O37+$F38,O37+0) -> 256.89 | P38: =if($I38="LD2",P37+$F38,P37+0) -> 191.74 | Q38: =if($I38="dummy",Q37+$F38,Q37+0) -> 81.12
B39: 1614 | C39: junk | I39: LD2 | J39: ps6=0 | L39: config narrow sparse | O39: =if($I39="LH2",O38+$F39,O38+0) -> 256.89 | P39: =if($I39="LD2",P38+$F39,P38+0) -> 191.74 | Q39: =if($I39="dummy",Q38+$F39,Q38+0) -> 81.12
B40: 1615 | C40: junk | I40: LD2 | J40: ps6=0 | O40: =if($I40="LH2",O39+$F40,O39+0) -> 256.89 | P40: =if($I40="LD2",P39+$F40,P39+0) -> 191.74 | Q40: =if($I40="dummy",Q39+$F40,Q39+0) -> 81.12
...

Sheet 3p_commissionning
E1: HMS mom | F1: HMS angle | G1: SHMS angle | H1: calo angle | I1: calo distance | L1: Collimator
A2: day | B2: run | C2: purpose | D2: Ibeam (uA) | J2: target | K2: Beam pass | M2: Presscale | N2: event # | O2: duration (min) | P2: Charge Accumulated | Q2: comments
A3: 45362 | B3: 5217 | C3: Elastic Calibration | D3: 30 | E3: 2.639 | F3: 35.96 | G3: 34.846 | H3: =G3-16.3 -> 18.546 | I3: 9.5 | J3: LH2 | K3: 3 | L3: L | M3: ps5=0 | N3: 81532 | O3: 30 | P3: 48.76
B4: 5218 | C4: Elastic Calibration | D4: 30 | E4: 2.639 | F4: 35.96 | G4: 34.846 | H4: =G4-16.3 -> 18.546 | I4: 9.5 | J4: LH2 | K4: 3 | L4: L | M4: ps5=0 | N4: 0 | O4: 11.27 | P4: 0 | Q4: junk
B5: 5219 | C5: Elastic Calibration | D5: 30 | E5: 2.639 | F5: 35.96 | G5: 34.846 | H5: =G5-16.3 -> 18.546 | I5: 9.5 | J5: LH2 | K5: 3 | L5: L | M5: ps5=0 | N5: 78066 | O5: 39.48 | P5: 46.69
B6: 5220 | C6: Elastic Calibration | D6: 30 | E6: 2.639 | F6: 35.96 | G6: 36.158 | H6: =G6-16.3 -> 19.858 | I6: 9.5 | J6: LH2 | K6: 3 | L6: L | M6: ps5=0 | N6: 93392 | O6: 28.54 | P6: 42.99
B7: 5221 | C7: Elastic Calibration | D7: 30 | E7: 2.639 | F7: 35.96 | G7: 36.158 | H7: =G7-16.3 -> 19.858 | I7: 9.5 | J7: LH2 | K7: 3 | L7: L | M7: ps5=0 | N7: 76805 | O7: 34.99 | P7: 35.86
B8: 5222 | C8: Elastic Calibration | D8: 30 | E8: 2.639 | F8: 35.96 | G8: 37.465 | H8: =G8-16.3 -> 21.165 | I8: 9.5 | J8: LH2 | K8: 3 | L8: L | M8: ps5=0 | N8: 89498 | O8: 29.14 | P8: 45.95 | Q8: first__epics_30 error maybe junk
B9: 5223 | C9: Elastic Calibration | D9: 30 | E9: 2.639 | F9: 35.96 | G9: 37.465 | H9: =G9-16.3 -> 21.165 | I9: 9.5 | J9: LH2 | K9: 3 | L9: L | M9: ps5=0 | N9: 86300 | O9: 29.59 | P9: 44.67
B10: 5224 | C10: Elastic Calibration | D10: 30 | E10: 2.639 | F10: 35.96 | G10: 37.465 | H10: =G10-16.3 -> 21.165 | I10: 9.5 | J10: LH2 | K10: 3 | L10: L | M10: ps5=0 | N10: 12897 | O10: 11 | P10: 6.72 | Q10: only 5mins of beam
B11: 5225 | C11: Elastic Calibration | D11: 30 | E11: 2.639 | F11: 35.96 | G11: 37.465 | H11: =G11-16.3 -> 21.165 | I11: 9.5 | J11: LH2 | K11: 3 | L11: L | M11: ps5=0 | N11: 72898 | O11: 23.93 | P11: 37.92
B12: 5226 | C12: Elastic Calibration | D12: 30 | E12: 2.639 | F12: 35.96 | G12: 34.86 | H12: =G12-16.3 -> 18.56 | I12: 9.5 | J12: LH2 | K12: 3 | L12: L | M12: ps5=0 | N12: 80111 | O12: 32.59 | P12: 47.31
B13: 5227 | C13: Elastic Calibration | D13: 30 | E13: 2.639 | F13: 35.96 | G13: 34.86 | H13: =G13-16.3 -> 18.56 | I13: 9.5 | J13: LH2 | K13: 3 | L13: L | M13: ps5=0 | N13: 95010 | O13: 34.09 | P13: 56.5
B14: 5228 | C14: Elastic Calibration | D14: 30 | E14: 2.639 | F14: 35.96 | G14: 36.155 | H14: =G14-16.3 -> 19.855 | I14: 9.5 | J14: LH2 | K14: 3 | L14: L | M14: ps5=0 | N14: 94876 | O14: 29.88 | P14: 44.14
B15: 5229 | C15: Elastic Calibration | D15: 30 | E15: 2.639 | F15: 35.96 | G15: 36.155 | H15: =G15-16.3 -> 19.855 | I15: 9.5 | J15: LH2 | K15: 3 | L15: L | M15: ps5=0 | N15: 31573 | O15: 12.88 | P15: 14.62
B16: 5230 | C16: Elastic Calibration | D16: 30 | E16: 2.639 | F16: 35.96 | G16: 36.155 | H16: =G16-16.3 -> 19.855 | I16: 9.5 | J16: LH2 | K16: 3 | L16: L | M16: ps5=0 | N16: 64668 | O16: 18.64 | P16: 30.06
B17: 5231 | C17: Elastic Calibration | D17: 30 | E17: 2.639 | F17: 35.96 | G17: 37.46 | H17: =G17-16.3 -> 21.16 | I17: 9.5 | J17: LH2 | K17: 3 | L17: L | M17: ps5=0 | N17: 93637 | O17: 28.97 | P17: 47.91
B18: 5232 | C18: Elastic Calibration | D18: 30 | E18: 2.639 | F18: 35.96 | G18: 37.46 | H18: =G18-16.3 -> 21.16 | I18: 9.5 | J18: LH2 | K18: 3 | L18: L | M18: ps5=0 | N18: 86276 | O18: 46.01 | P18: 43.53
B19: 5233 | C19: Elastic Calibration | D19: 30 | E19: 2.639 | F19: 35.96 | G19: 34.855 | H19: =G19-16.3 -> 18.555 | I19: 9.5 | J19: LH2 | K19: 3 | L19: L | M19: ps5=0 | N19: 81166 | O19: 29.02 | P19: 47.61
B20: 5234 | C20: Elastic Calibration | D20: 30 | E20: 2.639 | F20: 35.96 | G20: 34.855 | H20: =G20-16.3 -> 18.555 | I20: 9.5 | J20: LH2 | K20: 3 | L20: L | M20: ps5=0 | N20: 77803 | O20: 29.64 | P20: 45.96
B21: 5235 | C21: Elastic Calibration | D21: 30 | E21: 2.639 | F21: 35.96 | G21: 36.155 | H21: =G21-16.3 -> 19.855 | I21: 9.5 | J21: LH2 | K21: 3 | L21: L | M21: ps5=0 | N21: 97749 | O21: 26.98 | P21: 45.31
B22: 5236 | C22: Elastic Calibration | D22: 30 | E22: 2.639 | F22: 35.96 | G22: 36.155 | H22: =G22-16.3 -> 19.855 | I22: 9.5 | J22: LH2 | K22: 3 | L22: L | M22: ps5=0 | N22: 85369 | O22: 25.15 | P22: 39.1
A24: 45404 | B24: 6151 | C24: Elastic Calibration | D24: 25 | E24: 2.639 | F24: 35.965 | G24: 37.47 | H24: =G24-16.55 -> 20.92 | I24: 9.5 | J24: LH2 | K24: 3 | L24: L | M24: ps5=0 | N24: 155820 | O24: 37.79 | P24: 35.61
B25: 6152 | C25: Elastic Calibration | D25: 25 | E25: 2.639 | F25: 35.965 | G25: 37.47 | H25: =G25-16.55 -> 20.92 | I25: 9.5 | J25: LH2 | K25: 3 | L25: L | M25: ps5=0 | N25: 143383 | O25: 29.26 | P25: 40
B26: 6153 | C26: Elastic Calibration | D26: 25 | E26: 2.639 | F26: 35.965 | G26: 36.17 | H26: =G26-16.55 -> 19.62 | I26: 9.5 | J26: LH3 | K26: 3 | L26: L | M26: ps5=0 | N26: 161322 | O26: 30.6 | P26: 43.05
A27: 45405 | B27: 6154 | C27: Elastic Calibration | D27: 25 | E27: 2.639 | F27: 35.965 | G27: 36.17 | H27: =G27-16.55 -> 19.62 | I27: 9.5 | J27: LH4 | K27: 3 | L27: L | M27: ps5=0 | N27: 171834 | O27: 31.56 | P27: 46.2
B28: 6155 | C28: Elastic Calibration | D28: 25 | E28: 2.639 | F28: 35.965 | G28: 34.86 | H28: =G28-16.55 -> 18.31 | I28: 9.5 | J28: LH5 | K28: 3 | L28: L | M28: ps5=0 | N28: 159684 | O28: 35.82 | P28: 44.19
B29: 6156 | C29: Elastic Calibration | D29: 25 | E29: 2.639 | F29: 35.965 | G29: 34.86 | H29: =G29-16.55 -> 18.31 | I29: 9.5 | J29: LH6 | K29: 3 | L29: L | M29: ps5=0 | N29: 149979 | O29: 32.14 | P29: 44.99
B30: 6157 | C30: Elastic Calibration | D30: 25 | E30: 2.639 | F30: 35.965 | G30: 37.47 | H30: =G30-16.55 -> 20.92 | I30: 9.5 | J30: LH7 | K30: 3 | L30: L | M30: ps5=0 | N30: 150337 | O30: 29.46 | P30: 43.03
B31: 6158 | C31: Elastic Calibration | D31: 25 | E31: 2.639 | F31: 35.965 | G31: 37.47 | H31: =G31-16.55 -> 20.92 | I31: 9.5 | J31: LH8 | K31: 3 | L31: L | M31: ps5=0 | N31: 149041 | O31: 30.04 | P31: 41.27
B32: 6159 | C32: Elastic Calibration | D32: 25 | E32: 2.639 | F32: 35.965 | G32: 36.17 | H32: =G32-16.55 -> 19.62 | I32: 9.5 | J32: LH9 | K32: 3 | L32: L | M32: ps5=0 | N32: 160994 | O32: 31.95 | P32: 41.03
B33: 6160 | C33: Elastic Calibration | D33: 25 | E33: 2.639 | F33: 35.965 | G33: 36.17 | H33: =G33-16.55 -> 19.62 | I33: 9.5 | J33: LH10 | K33: 3 | L33: L | M33: ps5=0 | N33: 167315 | O33: 32.49 | P33: 43.02
B34: 6161 | C34: Elastic Calibration | D34: 25 | E34: 2.639 | F34: 35.965 | G34: 34.86 | H34: =G34-16.55 -> 18.31 | I34: 9.5 | J34: LH11 | K34: 3 | L34: L | M34: ps5=0 | N34: 166122 | O34: 34.4 | P34: 51.06
B35: 6162 | C35: Elastic Calibration | D35: 25 | E35: 2.639 | F35: 35.965 | G35: 34.86 | H35: =G35-16.55 -> 18.31 | I35: 9.5 | J35: LH12 | K35: 3 | L35: L | M35: ps5=0 | N35: 152260 | O35: 31.57 | P35: 46.96
B36: 6163 | C36: Elastic Calibration | D36: 25 | E36: 2.639 | F36: 35.965 | G36: 37.47 | H36: =G36-16.55 -> 20.92 | I36: 9.5 | J36: LH13 | K36: 3 | L36: L | M36: ps5=0 | N36: 124207 | O36: 26.02 | P36: 33.58
B37: 6164 | C37: Elastic Calibration | D37: 25 | E37: 2.639 | F37: 35.965 | G37: 37.47 | H37: =G37-16.55 -> 20.92 | I37: 9.5 | J37: LH14 | K37: 3 | L37: L | M37: ps5=0 | N37: 175646 | O37: 36.45 | P37: 47.98
B38: 6165 | C38: Elastic Calibration | D38: 25 | E38: 2.639 | F38: 35.965 | G38: 36.17 | H38: =G38-16.55 -> 19.62 | I38: 9.5 | J38: LH15 | K38: 3 | L38: L | M38: ps5=0 | N38: 161712 | O38: 31.45 | P38: 42.28
B39: 6166 | C39: Elastic Calibration | D39: 25 | E39: 2.639 | F39: 35.965 | G39: 36.17 | H39: =G39-16.55 -> 19.62 | I39: 9.5 | J39: LH15 | K39: 3 | L39: L | M39: ps5=0 | N39: 170832 | O39: 31.36 | P39: 46.39
... B41: 6168 | C41: Elastic Calibration | D41: 25 | E41: 2.639 | F41: 35.965 | G41: 34.86 | H41: =G41-16.55 -> 18.31 | I41: 9.5 | J41: LH15 | K41: 3 | L41: L | M41: ps5=0 | N41: 82420 | O41: 18.18 | P41: 24.04
A43: 45421 | C43: HMS Elastic Production

Sheet Sheet12
F1: HMS mom | G1: HMS angle | H1: SHMS angle | I1: calo angle | L1: calo distance | N1: Required Charge Total (Coulomb) | Q1: % of goal | R1: % of goal | S1: % of goal
F2: -6.667 GeV | G2: 12.493 deg | H2: 35.446 | I2: 19.146 | L2: 4m | N2: ='Totals % Goal'!F17 -> 0.7 | Q2: =MAX(Q5:Q997)/(N2*1000) -> 0.90134286 | R2: =MAX(R5:R997)/(N2*1000) -> 0.74034286 | S2: =MAX(S5:S997)/MAX(Q5:Q997) -> 0.1239896
Q3: accumulated charge (mC)
A4: day | B4: run | C4: Type | D4: SHMS angle | E4: Ibeam (uA) | F4: charge (mC) | G4: TS6 event # | H4: duration (min) | I4: target | J4: prescale | K4: coin status | O4: Clust Pair Thresh | P4: Clust read thresh | Q4: LH2 | R4: LD2 | S4: Dummy
A5: 45313 | B5: 3783 | C5: junk | D5: 35.441 | E5: 35 | F5: 0 | G5: 49484 | H5: 0.34 | I5: LH2 | J5: ps6=0 | K5: sparse | O5: =if(K5="low","140MeV","750MeV") -> 750MeV | P5: =if(K5="low","140MeV","650MeV") -> 650MeV | Q5: =if($I5="LH2",0+$F5,0) -> 0 | R5: 0 | S5: 0
B6: 3784 | C6: production | D6: 35.441 | E6: 35 | F6: 100 | G6: 0 | H6: 60 | I6: LH2 | J6: ps6=0 | K6: sparse | L6: no end of run coda entry | O6: =if(K6="low","140MeV","750MeV") -> 750MeV | P6: =if(K6="low","140MeV","650MeV") -> 650MeV | Q6: =if($I6="LH2",Q5+$F6,Q5+0) -> 100 | R6: =if($I6="LD2",R5+$F6,R5+0) -> 0 | S6: =if($I6="dummy",S5+$F6,S5+0) -> 0
B7: 3785 | C7: production | D7: 35.441 | E7: 35 | F7: 102.1 | G7: 10850314 | H7: 74.85 | I7: LH2 | J7: ps6=0 | K7: sparse | O7: =if(K7="low","140MeV","750MeV") -> 750MeV | P7: =if(K7="low","140MeV","650MeV") -> 650MeV | Q7: =if($I7="LH2",Q6+$F7,Q6+0) -> 202.1 | R7: =if($I7="LD2",R6+$F7,R6+0) -> 0 | S7: =if($I7="dummy",S6+$F7,S6+0) -> 0
B8: 3786 | C8: production | D8: 35.441 | E8: 20 | F8: 23.73 | G8: 1407225 | H8: 20.56 | I8: LH2 | J8: ps6=0 | K8: sparse | O8: =if(K8="low","140MeV","750MeV") -> 750MeV | P8: =if(K8="low","140MeV","650MeV") -> 650MeV | Q8: =if($I8="LH2",Q7+$F8,Q7+0) -> 225.83 | R8: =if($I8="LD2",R7+$F8,R7+0) -> 0 | S8: =if($I8="dummy",S7+$F8,S7+0) -> 0
B9: 3787 | C9: production | D9: 35.441 | E9: 10 | F9: 22.92 | G9: 752480 | H9: 38.88 | I9: LH2 | J9: ps6=0 | K9: sparse | O9: =if(K9="low","140MeV","750MeV") -> 750MeV | P9: =if(K9="low","140MeV","650MeV") -> 650MeV | Q9: =if($I9="LH2",Q8+$F9,Q8+0) -> 248.75 | R9: =if($I9="LD2",R8+$F9,R8+0) -> 0 | S9: =if($I9="dummy",S8+$F9,S8+0) -> 0
B10: 3788 | C10: efficiency | D10: 35.441 | E10: 20 | F10: 23.68 | G10: 1451933 | H10: 20.11 | I10: LH2 | J10: ps4=0 | K10: sparse | O10: =if(K10="low","140MeV","750MeV") -> 750MeV | P10: =if(K10="low","140MeV","650MeV") -> 650MeV | Q10: =if($I10="LH2",Q9+$F10,Q9+0) -> 272.43 | R10: =if($I10="LD2",R9+$F10,R9+0) -> 0 | S10: =if($I10="dummy",S9+$F10,S9+0) -> 0
B11: 3789 | C11: junk | D11: 35.441 | E11: 35 | F11: 0 | G11: 112853 | H11: 0.56 | I11: LH2 | J11: ps6=2 | K11: off | O11: =if(K11="low","140MeV","750MeV") -> 750MeV | P11: =if(K11="low","140MeV","650MeV") -> 650MeV | Q11: =if($I11="LH2",Q10+$F11,Q10+0) -> 272.43 | R11: =if($I11="LD2",R10+$F11,R10+0) -> 0 | S11: =if($I11="dummy",S10+$F11,S10+0) -> 0
B12: 3790 | C12: production | D12: 35.441 | E12: 35 | F12: 27.67 | G12: 2540927 | H12: 14.33 | I12: LH2 | J12: ps6=3 | K12: off | O12: =if(K12="low","140MeV","750MeV") -> 750MeV | P12: =if(K12="low","140MeV","650MeV") -> 650MeV | Q12: =if($I12="LH2",Q11+$F12,Q11+0) -> 300.1 | R12: =if($I12="LD2",R11+$F12,R11+0) -> 0 | S12: =if($I12="dummy",S11+$F12,S11+0) -> 0
B13: 3791 | C13: production | D13: 35.441 | E13: 30 | F13: 25.94 | G13: 2497587 | H13: 14.38 | I13: dummy | J13: ps6=0 | K13: sparse | O13: =if(K13="low","140MeV","750MeV") -> 750MeV | P13: =if(K13="low","140MeV","650MeV") -> 650MeV | Q13: =if($I13="LH2",Q12+$F13,Q12+0) -> 300.1 | R13: =if($I13="LD2",R12+$F13,R12+0) -> 0 | S13: =if($I13="dummy",S12+$F13,S12+0) -> 25.94
B14: 3792 | C14: junk | D14: 35.441 | E14: 30 | F14: 0 | G14: 1192 | H14: 0.5 | I14: dummy | J14: ps6=0 | K14: sparse | O14: =if(K14="low","140MeV","750MeV") -> 750MeV | P14: =if(K14="low","140MeV","650MeV") -> 650MeV | Q14: =if($I14="LH2",Q13+$F14,Q13+0) -> 300.1 | R14: =if($I14="LD2",R13+$F14,R13+0) -> 0 | S14: =if($I14="dummy",S13+$F14,S13+0) -> 25.94
B15: 3793 | C15: production | D15: 35.441 | E15: 20 | F15: 24 | G15: 1430258 | H15: 22.57 | I15: LD2 | J15: ps6=0 | K15: sparse | O15: =if(K15="low","140MeV","750MeV") -> 750MeV | P15: =if(K15="low","140MeV","650MeV") -> 650MeV | Q15: =if($I15="LH2",Q14+$F15,Q14+0) -> 300.1 | R15: =if($I15="LD2",R14+$F15,R14+0) -> 24 | S15: =if($I15="dummy",S14+$F15,S14+0) -> 25.94
B16: 3794 | C16: production | D16: 35.441 | E16: 20 | F16: 10.19 | G16: 4130667 | H16: 11.51 | I16: LD2 | J16: ps6=0 | K16: sparse | O16: =if(K16="low","140MeV","750MeV") -> 750MeV | P16: =if(K16="low","140MeV","650MeV") -> 650MeV | Q16: =if($I16="LH2",Q15+$F16,Q15+0) -> 300.1 | R16: =if($I16="LD2",R15+$F16,R15+0) -> 34.19 | S16: =if($I16="dummy",S15+$F16,S15+0) -> 25.94
B17: 3795 | C17: junk | D17: 35.441 | E17: 20 | F17: 0 | G17: 0 | H17: 27 | I17: LD2 | J17: ps6=0 | K17: sparse | L17: daq crashed | O17: =if(K17="low","140MeV","750MeV") -> 750MeV | P17: =if(K17="low","140MeV","650MeV") -> 650MeV | Q17: =if($I17="LH2",Q16+$F17,Q16+0) -> 300.1 | R17: =if($I17="LD2",R16+$F17,R16+0) -> 34.19 | S17: =if($I17="dummy",S16+$F17,S16+0) -> 25.94
B18: 3796 | C18: production | D18: 35.441 | E18: 20 | F18: 39.15 | G18: 11560022 | H18: 57.1 | I18: LD2 | J18: ps6=0 | K18: sparse | O18: =if(K18="low","140MeV","750MeV") -> 750MeV | P18: =if(K18="low","140MeV","650MeV") -> 650MeV | Q18: =if($I18="LH2",Q17+$F18,Q17+0) -> 300.1 | R18: =if($I18="LD2",R17+$F18,R17+0) -> 73.34 | S18: =if($I18="dummy",S17+$F18,S17+0) -> 25.94
B19: 3797 | C19: production | D19: 35.441 | E19: 12 | F19: 39.56 | G19: 11684360 | H19: 58.38 | I19: LD2 | J19: ps6=0 | K19: sparse | O19: =if(K19="low","140MeV","750MeV") -> 750MeV | P19: =if(K19="low","140MeV","650MeV") -> 650MeV | Q19: =if($I19="LH2",Q18+$F19,Q18+0) -> 300.1 | R19: =if($I19="LD2",R18+$F19,R18+0) -> 112.9 | S19: =if($I19="dummy",S18+$F19,S18+0) -> 25.94
B20: 3798 | C20: production | D20: 35.441 | E20: 12 | F20: 41.85 | G20: 12269246 | H20: 61.11 | I20: LD2 | J20: ps6=0 | K20: sparse | O20: =if(K20="low","140MeV","750MeV") -> 750MeV | P20: =if(K20="low","140MeV","650MeV") -> 650MeV | Q20: =if($I20="LH2",Q19+$F20,Q19+0) -> 300.1 | R20: =if($I20="LD2",R19+$F20,R19+0) -> 154.75 | S20: =if($I20="dummy",S19+$F20,S19+0) -> 25.94
B21: 3799 | C21: production | D21: 35.441 | E21: 12 | F21: 38.91 | G21: 11528307 | H21: 57.85 | I21: LD2 | J21: ps6=0 | K21: sparse | O21: =if(K21="low","140MeV","750MeV") -> 750MeV | P21: =if(K21="low","140MeV","650MeV") -> 650MeV | Q21: =if($I21="LH2",Q20+$F21,Q20+0) -> 300.1 | R21: =if($I21="LD2",R20+$F21,R20+0) -> 193.66 | S21: =if($I21="dummy",S20+$F21,S20+0) -> 25.94
B22: 3800 | C22: production | D22: 35.441 | E22: 10 | F22: 10.1 | G22: 2430268 | H22: 19.45 | I22: LD2 | J22: ps6=0 | K22: sparse | O22: =if(K22="low","140MeV","750MeV") -> 750MeV | P22: =if(K22="low","140MeV","650MeV") -> 650MeV | Q22: =if($I22="LH2",Q21+$F22,Q21+0) -> 300.1 | R22: =if($I22="LD2",R21+$F22,R21+0) -> 203.76 | S22: =if($I22="dummy",S21+$F22,S21+0) -> 25.94
B23: 3801 | C23: production | D23: 35.441 | E23: 5 | F23: 11.79 | G23: 1356310 | H23: 38.19 | I23: LD2 | J23: ps6=0 | K23: sparse | O23: =if(K23="low","140MeV","750MeV") -> 750MeV | P23: =if(K23="low","140MeV","650MeV") -> 650MeV | Q23: =if($I23="LH2",Q22+$F23,Q22+0) -> 300.1 | R23: =if($I23="LD2",R22+$F23,R22+0) -> 215.55 | S23: =if($I23="dummy",S22+$F23,S22+0) -> 25.94
B24: 3802 | C24: junk | D24: 35.441 | E24: 10 | F24: 0 | G24: 219620 | H24: 1.6 | I24: LD2 | J24: ps4=0 | K24: sparse | L24: HMS Q1 Trip out | O24: =if(K24="low","140MeV","750MeV") -> 750MeV | P24: =if(K24="low","140MeV","650MeV") -> 650MeV | Q24: =if($I24="LH2",Q23+$F24,Q23+0) -> 300.1 | R24: =if($I24="LD2",R23+$F24,R23+0) -> 215.55 | S24: =if($I24="dummy",S23+$F24,S23+0) -> 25.94
B25: 3803 | C25: junk | D25: 35.441 | E25: 10 | F25: 0 | G25: 2873203 | H25: 19.84 | I25: LD2 | J25: ps4=0 | K25: sparse | L25: ps6 and ps4 on | O25: =if(K25="low","140MeV","750MeV") -> 750MeV | P25: =if(K25="low","140MeV","650MeV") -> 650MeV | Q25: =if($I25="LH2",Q24+$F25,Q24+0) -> 300.1 | R25: =if($I25="LD2",R24+$F25,R24+0) -> 215.55 | S25: =if($I25="dummy",S24+$F25,S24+0) -> 25.94
B26: 3804 | C26: efficiency | D26: 35.441 | E26: 10 | F26: 8.55 | G26: 2045840 | H26: 15 | I26: LD2 | J26: ps4=0 | K26: sparse | O26: =if(K26="low","140MeV","750MeV") -> 750MeV | P26: =if(K26="low","140MeV","650MeV") -> 650MeV | Q26: =if($I26="LH2",Q25+$F26,Q25+0) -> 300.1 | R26: =if($I26="LD2",R25+$F26,R25+0) -> 224.1 | S26: =if($I26="dummy",S25+$F26,S25+0) -> 25.94
B27: 3805 | C27: junk | D27: 35.441 | E27: 12 | F27: 0 | G27: 74735 | H27: 0 | I27: LD2 | J27: ps6=1 | K27: off | O27: =if(K27="low","140MeV","750MeV") -> 750MeV | P27: =if(K27="low","140MeV","650MeV") -> 650MeV | Q27: =if($I27="LH2",Q26+$F27,Q26+0) -> 300.1 | R27: =if($I27="LD2",R26+$F27,R26+0) -> 224.1 | S27: =if($I27="dummy",S26+$F27,S26+0) -> 25.94
B28: 3806 | C28: production | D28: 35.441 | E28: 12 | F28: 10.94 | G28: 2662074 | H28: 15.94 | I28: LD2 | J28: ps6=3 | K28: off | O28: =if(K28="low","140MeV","750MeV") -> 750MeV | P28: =if(K28="low","140MeV","650MeV") -> 650MeV | Q28: =if($I28="LH2",Q27+$F28,Q27+0) -> 300.1 | R28: =if($I28="LD2",R27+$F28,R27+0) -> 235.04 | S28: =if($I28="dummy",S27+$F28,S27+0) -> 25.94
A29: 45314 | B29: 3833 | C29: junk | D29: 35.438 | E29: 40 | F29: 0 | G29: 8672 | H29: 0.05 | I29: LH2 | J29: ps6=0 | K29: sparse | O29: =if(K29="low","140MeV","750MeV") -> 750MeV | P29: =if(K29="low","140MeV","650MeV") -> 650MeV | Q29: =if($I29="LH2",Q28+$F29,Q28+0) -> 300.1 | R29: =if($I29="LD2",R28+$F29,R28+0) -> 235.04 | S29: =if($I29="dummy",S28+$F29,S28+0) -> 25.94
B30: 3834 | C30: production | D30: 35.438 | E30: 40 | F30: 99.03 | G30: 7654460 | H30: 57.54 | I30: LH2 | J30: ps6=0 | K30: sparse | O30: =if(K30="low","140MeV","750MeV") -> 750MeV | P30: =if(K30="low","140MeV","650MeV") -> 650MeV | Q30: =if($I30="LH2",Q29+$F30,Q29+0) -> 399.13 | R30: =if($I30="LD2",R29+#REF!,R29+0) -> 235.04 | S30: =if($I30="dummy",S29+#REF!,S29+0) -> 25.94
B31: 3835 | C31: production | D31: 35.438 | E31: 40 | F31: 115 | G31: 9034123 | H31: 57.4 | I31: LH2 | J31: ps6=0 | K31: sparse | O31: =if(K31="low","140MeV","750MeV") -> 750MeV | P31: =if(K31="low","140MeV","650MeV") -> 650MeV | Q31: =if($I31="LH2",Q30+$F31,Q30+0) -> 514.13 | R31: =if($I31="LD2",R30+$F31,R30+0) -> 235.04 | S31: =if($I31="dummy",S30+$F31,S30+0) -> 25.94
B32: 3836 | C32: production | D32: 35.438 | E32: 20 | F32: 22.28 | G32: 765153 | H32: 19.25 | I32: LH2 | J32: ps6=0 | K32: sparse | O32: =if(K32="low","140MeV","750MeV") -> 750MeV | P32: =if(K32="low","140MeV","650MeV") -> 650MeV | Q32: =if($I32="LH2",Q31+$F32,Q31+0) -> 536.41 | R32: =if($I32="LD2",R31+$F32,R31+0) -> 235.04 | S32: =if($I32="dummy",S31+$F32,S31+0) -> 25.94
B33: 3837 | C33: production | D33: 35.438 | E33: 10 | F33: 22.87 | G33: 470880 | H33: 39.5 | I33: LH2 | J33: ps6=0 | K33: sparse | O33: =if(K33="low","140MeV","750MeV") -> 750MeV | P33: =if(K33="low","140MeV","650MeV") -> 650MeV | Q33: =if($I33="LH2",Q32+$F33,Q32+0) -> 559.28 | R33: =if($I33="LD2",R32+$F33,R32+0) -> 235.04 | S33: =if($I33="dummy",S32+$F33,S32+0) -> 25.94
B34: 3838 | C34: junk | D34: 35.438 | E34: 20 | F34: 0 | G34: 0 | H34: 5 | I34: LH2 | J34: ps4=0 | K34: sparse | L34: No end of run entry due to coda issue | O34: =if(K34="low","140MeV","750MeV") -> 750MeV | P34: =if(K34="low","140MeV","650MeV") -> 650MeV | Q34: =if($I34="LH2",Q33+$F34,Q33+0) -> 559.28 | R34: =if($I34="LD2",R33+$F34,R33+0) -> 235.04 | S34: =if($I34="dummy",S33+$F34,S33+0) -> 25.94
B35: 3839 | C35: efficiency | D35: 35.438 | E35: 20 | F35: 20 | G35: 0 | H35: 21 | I35: LH2 | J35: ps4=0 | K35: sparse | L35: No end of run entry due to coda issue | O35: =if(K35="low","140MeV","750MeV") -> 750MeV | P35: =if(K35="low","140MeV","650MeV") -> 650MeV | Q35: =if($I35="LH2",Q34+$F35,Q34+0) -> 579.28 | R35: =if($I35="LD2",R34+$F35,R34+0) -> 235.04 | S35: =if($I35="dummy",S34+$F35,S34+0) -> 25.94
B36: 3840 | C36: efficiency | D36: 35.438 | E36: 20 | F36: 21.62 | G36: 761558 | H36: 19.14 | I36: LH2 | J36: ps4=0 | K36: sparse | O36: =if(K36="low","140MeV","750MeV") -> 750MeV | P36: =if(K36="low","140MeV","650MeV") -> 650MeV | Q36: =if($I36="LH2",Q35+$F36,Q35+0) -> 600.9 | R36: =if($I36="LD2",R35+$F36,R35+0) -> 235.04 | S36: =if($I36="dummy",S35+$F36,S35+0) -> 25.94
B37: 3841 | C37: production | D37: 35.438 | E37: 40 | F37: 30.04 | G37: 1726662 | H37: 14.82 | I37: LH2 | J37: ps6=3 | K37: sparse | O37: =if(K37="low","140MeV","750MeV") -> 750MeV | P37: =if(K37="low","140MeV","650MeV") -> 650MeV | Q37: =if($I37="LH2",Q36+$F37,Q36+0) -> 630.94 | R37: =if($I37="LD2",R36+$F37,R36+0) -> 235.04 | S37: =if($I37="dummy",S36+$F37,S36+0) -> 25.94
B38: 3842 | C38: production | D38: 35.438 | E38: 30 | F38: 26.03 | G38: 1454728 | H38: 14.62 | I38: dummy | J38: ps6=0 | K38: sparse | O38: =if(K38="low","140MeV","750MeV") -> 750MeV | P38: =if(K38="low","140MeV","650MeV") -> 650MeV | Q38: =if($I38="LH2",Q37+$F38,Q37+0) -> 630.94 | R38: =if($I38="LD2",R37+$F38,R37+0) -> 235.04 | S38: =if($I38="dummy",S37+$F38,S37+0) -> 51.97
B39: 3843 | C39: production | D39: 35.438 | E39: 20 | F39: 26.26 | G39: 860611 | H39: 22.45 | I39: dummy | J39: ps6=0 | K39: sparse | O39: =if(K39="low","140MeV","750MeV") -> 750MeV | P39: =if(K39="low","140MeV","650MeV") -> 650MeV | Q39: =if($I39="LH2",Q38+$F39,Q38+0) -> 630.94 | R39: =if($I39="LD2",R38+$F39,R38+0) -> 235.04 | S39: =if($I39="dummy",S38+$F39,S38+0) -> 78.23
A40: 45315 | B40: 3844 | C40: production | D40: 35.438 | E40: 12 | F40: 37.04 | G40: 6474599 | H40: 57.18 | I40: LD2 | J40: ps6=0 | K40: sparse | O40: =if(K40="low","140MeV","750MeV") -> 750MeV | P40: =if(K40="low","140MeV","650MeV") -> 650MeV | Q40: =if($I40="LH2",Q39+#REF!,Q39+0) -> 630.94 | R40: =if($I40="LD2",R39+$F40,R39+0) -> 272.08 | S40: =if($I40="dummy",S39+#REF!,S39+0) -> 78.23
...

Sheet Sheet13
A1: Kin_x50_2'' | F1: HMS mom | G1: HMS angle | H1: SHMS angle | I1: calo angle | L1: calo distance | N1: Required Charge Total (Coulomb) | Q1: % of goal | R1: % of goal | S1: % of goal
F2: -6.667 GeV | G2: 12.493 deg | H2: =36.88+1.43 -> 38.31 | I2: =H2-16.3 -> 22.01 | L2: 4m | N2: ='Totals % Goal'!F18 -> 0.7 | Q2: =MAX(Q5:Q997)/(N2*1000) -> 0.83168571 | R2: =MAX(R5:R997)/(N2*1000) -> 0.919 | S2: =MAX(S5:S997)/MAX(Q5:Q997) -> 0.16125597
Q3: accumulated charge (mC)
A4: day | B4: run | C4: type | D4: SHMS angle | E4: Ibeam (uA) | F4: charge (mC) | G4: TS6 event # | H4: duration (min) | I4: target | J4: prescale | K4: coin status | O4: Clust Pair Thresh | P4: Clust read thresh | Q4: LH2 | R4: LD2 | S4: Dummy
A5: 45314 | B5: 3807 | C5: junk | D5: 37.995 | E5: 35 | F5: 0 | G5: 0 | H5: 0 | I5: LH2 | J5: ps6=0 | K5: sparse | L5: Coda crash no end of run log | O5: =if(L124="low","140MeV","750MeV") -> 750MeV | P5: =if(L124="low","140MeV","650MeV") -> 650MeV | Q5: =if($I5="LH2",0+$F5,0) -> 0 | R5: 0 | S5: 0
B6: 3808 | C6: production | D6: 37.995 | E6: 30 | F6: 110.44 | G6: 7495265 | H6: 56.67 | I6: LH2 | J6: ps6=0 | K6: sparse | O6: =if(L125="low","140MeV","750MeV") -> 750MeV | P6: =if(L125="low","140MeV","650MeV") -> 650MeV | Q6: =if($I6="LH2",Q5+$F6,Q5+0) -> 110.44 | R6: =if($I6="LD2",R5+$F6,R5+0) -> 0 | S6: =if($I6="dummy",S5+$F6,S5+0) -> 0
B7: 3809 | C7: junk | D7: 37.995 | E7: 35 | F7: 0 | G7: 32663 | H7: 13.3 | I7: LH2 | J7: ps6=0 | K7: sparse | L7: no beam | O7: =if(L126="low","140MeV","750MeV") -> 750MeV | P7: =if(L126="low","140MeV","650MeV") -> 650MeV | Q7: =if($I7="LH2",Q6+$F7,Q6+0) -> 110.44 | R7: =if($I7="LD2",R6+$F7,R6+0) -> 0 | S7: =if($I7="dummy",S6+$F7,S6+0) -> 0
B8: 3810 | C8: production | D8: 37.995 | E8: 35 | F8: 105.96 | G8: 7111535 | H8: 56.79 | I8: LH2 | J8: ps6=0 | K8: sparse | O8: =if(L127="low","140MeV","750MeV") -> 750MeV | P8: =if(L127="low","140MeV","650MeV") -> 650MeV | Q8: =if($I8="LH2",Q7+$F8,Q7+0) -> 216.4 | R8: =if($I8="LD2",R7+$F8,R7+0) -> 0 | S8: =if($I8="dummy",S7+$F8,S7+0) -> 0
B9: 3811 | C9: junk | D9: 37.995 | E9: 35 | F9: 0 | G9: 84247 | H9: 0.5 | I9: LH2 | J9: ps6=0 | K9: sparse | O9: =if(L128="low","140MeV","750MeV") -> 750MeV | P9: =if(L128="low","140MeV","650MeV") -> 650MeV | Q9: =if($I9="LH2",Q8+$F9,Q8+0) -> 216.4 | R9: =if($I9="LD2",R8+$F9,R8+0) -> 0 | S9: =if($I9="dummy",S8+$F9,S8+0) -> 0
B10: 3812 | C10: production | D10: 37.995 | E10: 20 | F10: 24.83 | G10: 919802 | H10: 23.98 | I10: LH2 | J10: ps6=0 | K10: sparse | O10: =if(L129="low","140MeV","750MeV") -> 750MeV | P10: =if(L129="low","140MeV","650MeV") -> 650MeV | Q10: =if($I10="LH2",Q9+$F10,Q9+0) -> 241.23 | R10: =if($I10="LD2",R9+$F10,R9+0) -> 0 | S10: =if($I10="dummy",S9+$F10,S9+0) -> 0
B11: 3813 | C11: production | D11: 37.995 | E11: 10 | F11: 23.1 | G11: 530416 | H11: 40.98 | I11: LH2 | J11: ps6=0 | K11: sparse | O11: =if(L130="low","140MeV","750MeV") -> 750MeV | P11: =if(L130="low","140MeV","650MeV") -> 650MeV | Q11: =if($I11="LH2",Q10+$F11,Q10+0) -> 264.33 | R11: =if($I11="LD2",R10+$F11,R10+0) -> 0 | S11: =if($I11="dummy",S10+$F11,S10+0) -> 0
B12: 3814 | C12: efficiency | D12: 37.995 | E12: 20 | F12: 17.77 | G12: 695701 | H12: 16.75 | I12: LH2 | J12: ps4=0 | K12: sparse | O12: =if(L131="low","140MeV","750MeV") -> 750MeV | P12: =if(L131="low","140MeV","650MeV") -> 650MeV | Q12: =if($I12="LH2",Q11+$F12,Q11+0) -> 282.1 | R12: =if($I12="LD2",R11+$F12,R11+0) -> 0 | S12: =if($I12="dummy",S11+$F12,S11+0) -> 0
B13: 3815 | C13: junk | D13: 37.995 | E13: 35 | F13: 0 | G13: 83274 | H13: 0.74 | I13: LH2 | J13: ps6=0 | K13: off | O13: =if(L132="low","140MeV","750MeV") -> 750MeV | P13: =if(L132="low","140MeV","650MeV") -> 650MeV | Q13: =if($I13="LH2",Q12+$F13,Q12+0) -> 282.1 | R13: =if($I13="LD2",R12+$F13,R12+0) -> 0 | S13: =if($I13="dummy",S12+$F13,S12+0) -> 0
B14: 3816 | C14: production | D14: 37.995 | E14: 35 | F14: 30.14 | G14: 12560 | H14: 15.36 | I14: LH2 | J14: ps6=2 | K14: off | O14: =if(L133="low","140MeV","750MeV") -> 750MeV | P14: =if(L133="low","140MeV","650MeV") -> 650MeV | Q14: =if($I14="LH2",Q13+$F14,Q13+0) -> 312.24 | R14: =if($I14="LD2",R13+$F14,R13+0) -> 0 | S14: =if($I14="dummy",S13+$F14,S13+0) -> 0
B15: 3817 | C15: production | D15: 37.995 | E15: 30 | F15: 26.61 | G15: 1487565 | H15: 18.23 | I15: dummy | J15: ps6=0 | K15: sparse | O15: =if(L134="low","140MeV","750MeV") -> 750MeV | P15: =if(L134="low","140MeV","650MeV") -> 650MeV | Q15: =if($I15="LH2",Q14+$F15,Q14+0) -> 312.24 | R15: =if($I15="LD2",R14+$F15,R14+0) -> 0 | S15: =if($I15="dummy",S14+$F15,S14+0) -> 26.61
B16: 3818 | C16: production | D16: 37.995 | E16: 20 | F16: 24.7 | G16: 882301 | H16: 21.38 | I16: dummy | J16: ps6=0 | K16: sparse | O16: =if(L135="low","140MeV","750MeV") -> 750MeV | P16: =if(L135="low","140MeV","650MeV") -> 650MeV | Q16: =if($I16="LH2",Q15+$F16,Q15+0) -> 312.24 | R16: =if($I16="LD2",R15+$F16,R15+0) -> 0 | S16: =if($I16="dummy",S15+$F16,S15+0) -> 51.31
B17: 3819 | C17: production | D17: 37.995 | E17: 15 | F17: 55.97 | G17: 10255099 | H17: 41.96 | I17: LD2 | J17: ps6=0 | K17: sparse | O17: =if(L136="low","140MeV","750MeV") -> 750MeV | P17: =if(L136="low","140MeV","650MeV") -> 650MeV | Q17: =if($I17="LH2",Q16+$F17,Q16+0) -> 312.24 | R17: =if($I17="LD2",R16+$F17,R16+0) -> 55.97 | S17: =if($I17="dummy",S16+$F17,S16+0) -> 51.31
B18: 3820 | C18: production | D18: 37.995 | E18: 15 | F18: 41.57 | G18: 10194233 | H18: 75.14 | I18: LD2 | J18: ps6=0 | K18: sparse | O18: =if(L137="low","140MeV","750MeV") -> 750MeV | P18: =if(L137="low","140MeV","650MeV") -> 650MeV | Q18: =if($I18="LH2",Q17+$F18,Q17+0) -> 312.24 | R18: =if($I18="LD2",R17+$F18,R17+0) -> 97.54 | S18: =if($I18="dummy",S17+$F18,S17+0) -> 51.31
B19: 3821 | C19: BCM Calibration | D19: 37.995 | E19: n/a | F19: 0 | G19: 0 | H19: n/a | I19: Out of beam | J19: ps6=0 | K19: sparse | L19: no end of run log | O19: =if(L138="low","140MeV","750MeV") -> 750MeV | P19: =if(L138="low","140MeV","650MeV") -> 650MeV | Q19: =if($I19="LH2",Q18+$F19,Q18+0) -> 312.24 | R19: =if($I19="LD2",R18+$F19,R18+0) -> 97.54 | S19: =if($I19="dummy",S18+$F19,S18+0) -> 51.31
B20: 3822 | C20: junk | D20: 37.995 | E20: 15 | F20: 0 | G20: 82056 | H20: 10.8 | I20: LD2 | J20: ps6=0 | K20: sparse | L20: no beam | O20: =if(L139="low","140MeV","750MeV") -> 750MeV | P20: =if(L139="low","140MeV","650MeV") -> 650MeV | Q20: =if($I20="LH2",Q19+$F20,Q19+0) -> 312.24 | R20: =if($I20="LD2",R19+$F20,R19+0) -> 97.54 | S20: =if($I20="dummy",S19+$F20,S19+0) -> 51.31
B21: 3823 | C21: production | D21: 37.995 | E21: 15 | F21: 45.1 | G21: 10484958 | H21: 57.6 | I21: LD2 | J21: ps6=0 | K21: sparse | O21: =if(L140="low","140MeV","750MeV") -> 750MeV | P21: =if(L140="low","140MeV","650MeV") -> 650MeV | Q21: =if($I21="LH2",Q20+$F21,Q20+0) -> 312.24 | R21: =if($I21="LD2",R20+$F21,R20+0) -> 142.64 | S21: =if($I21="dummy",S20+$F21,S20+0) -> 51.31
B22: 3824 | C22: production | D22: 37.995 | E22: 15 | F22: 44.74 | G22: 10523687 | H22: 60.12 | I22: LD2 | J22: ps6=0 | K22: sparse | O22: =if(L141="low","140MeV","750MeV") -> 750MeV | P22: =if(L141="low","140MeV","650MeV") -> 650MeV | Q22: =if($I22="LH2",Q21+$F22,Q21+0) -> 312.24 | R22: =if($I22="LD2",R21+$F22,R21+0) -> 187.38 | S22: =if($I22="dummy",S21+$F22,S21+0) -> 51.31
B23: 3825 | C23: production | D23: 37.995 | E23: 15 | F23: 43.26 | G23: 10126938 | H23: 57.2 | I23: LD2 | J23: ps6=0 | K23: sparse | O23: =if(L142="low","140MeV","750MeV") -> 750MeV | P23: =if(L142="low","140MeV","650MeV") -> 650MeV | Q23: =if($I23="LH2",Q22+$F23,Q22+0) -> 312.24 | R23: =if($I23="LD2",R22+$F23,R22+0) -> 230.64 | S23: =if($I23="dummy",S22+$F23,S22+0) -> 51.31
B24: 3826 | C24: production | D24: 37.995 | E24: 10 | F24: 11.44 | G24: 1665531 | H24: 19.62 | I24: LD2 | J24: ps6=0 | K24: sparse | O24: =if(L143="low","140MeV","750MeV") -> 750MeV | P24: =if(L143="low","140MeV","650MeV") -> 650MeV | Q24: =if($I24="LH2",Q23+$F24,Q23+0) -> 312.24 | R24: =if($I24="LD2",R23+$F24,R23+0) -> 242.08 | S24: =if($I24="dummy",S23+$F24,S23+0) -> 51.31
B25: 3827 | C25: production | D25: 37.995 | E25: 5 | F25: 12 | G25: 892310 | H25: 39.44 | I25: LD2 | J25: ps6=0 | K25: sparse | O25: =if(L144="low","140MeV","750MeV") -> 750MeV | P25: =if(L144="low","140MeV","650MeV") -> 650MeV | Q25: =if($I25="LH2",Q24+$F25,Q24+0) -> 312.24 | R25: =if($I25="LD2",R24+$F25,R24+0) -> 254.08 | S25: =if($I25="dummy",S24+$F25,S24+0) -> 51.31
B26: 3828 | C26: efficiency | D26: 37.995 | E26: 10 | F26: 12.94 | G26: 1913666 | H26: 21.53 | I26: LD2 | J26: ps4=0 | K26: sparse | O26: =if(L145="low","140MeV","750MeV") -> 750MeV | P26: =if(L145="low","140MeV","650MeV") -> 650MeV | Q26: =if($I26="LH2",Q25+$F26,Q25+0) -> 312.24 | R26: =if($I26="LD2",R25+$F26,R25+0) -> 267.02 | S26: =if($I26="dummy",S25+$F26,S25+0) -> 51.31
B27: 3829 | C27: junk | D27: 37.995 | E27: 15 | F27: 0 | G27: 27029 | H27: 0.14 | I27: LD2 | J27: ps6=0 | K27: sparse | O27: =if(L146="low","140MeV","750MeV") -> 750MeV | P27: =if(L146="low","140MeV","650MeV") -> 650MeV | Q27: =if($I27="LH2",Q26+$F27,Q26+0) -> 312.24 | R27: =if($I27="LD2",R26+$F27,R26+0) -> 267.02 | S27: =if($I27="dummy",S26+$F27,S26+0) -> 51.31
